Workbook

Sheet Topic_words
B1: topic | C1: topic_distribution
A2: =IF(COUNTIF(Topic_importance!$A$2:$A$21,Topic_words!B2),1,0) -> 1 | B2: 0 | C2: {'asset': np.float64(0.88078287225586), 'activity': np.float64(0.31787455908177226), 'also': np.float64(0.28855921863405226), 'account': np.float64(0.11253551474809065), 'area': np.float64(0.08390375585003117), 'action': np.float64(0.08219763156052116), 'approval': np.float64(0.06333951502962484), 'act': np.float64(0.05120364765108197), 'aim': np.float64(0.04238249047644732), 'asia': np.float64(0.029645263379161943), 'amt': np.float64(0.028859100410800472), 'remaining': np.float64(0.023847838963113193), 'agreed': np.float64(0.018012145893573736), 'even': np.float64(0.01730848535310542), 'association': np.float64(0.01653758404919214), 'icaap': np.float64(0.015168892852630757), 'bbb': np.float64(0.014443011867123727), 'usa': np.float64(0.013677688772761772), 'iaa': np.float64(0.012024625171166866), 'iaaa': np.float64(0.012024625171166866), 'ama': np.float64(0.011962837342979597), 'eve': np.float64(0.010164964392125114), 'etc': np.float64(0.008710646145723805), 'aaa': np.float64(0.007517534328866078), 'ccc': np.float64(0.00690896913571638), 'assist': np.float64(0.006616278999680272), 'acute': np.float64(0.006198593254320788), 'baa': np.float64(0.006150471970222687), 'erc': np.float64(0.006021579508125208), 'aear': np.float64(0.005975883301615032), 'approve': np.float64(0.00560721792105267), 'caa': np.float64(0.00551618057353995), 'avg': np.float64(0.005398671411700234), 'afc': np.float64(0.005143955021559263), 'abcp': np.float64(0.005080164615097583), 'bac': np.float64(0.004864829601325589), 'alm': np.float64(0.0046368838966748685), 'aware': np.float64(0.0039854047169597204), 'always': np.float64(0.003928119897855127), 'alert': np.float64(0.0039047503901806753), 'aml': np.float64(0.0031921463061460784), 'alia': np.float64(0.002672535981602553), 'agent': np.float64(0.0024893900024677996), 'assignment': np.float64(0.002435461913458983), 'alpha': np.float64(0.002404925034233373), 'attribute': np.float64(0.0021272214988738813), 'iam': np.float64(0.0019017125042198593), 'arching': np.float64(0.0017497277947295332), 'rtc': np.float64(0.0016054614320566108), 'rea': np.float64(0.0015811766969675007), 'ima': np.float64(0.001575893640901832), 'agm': np.float64(0.001457119284649872), 'automatic': np.float64(0.0013959944155440504), 'eea': np.float64(0.0013706422161678126), 'axis': np.float64(0.0012024625171166866), 'ups': np.float64(0.0010815346724446326), 'acams': np.float64(0.0010758862512242067), 'auto': np.float64(0.0010490105099695312), 'psps': np.float64(0.0010002399929142163), 'ante': np.float64(0.0009729659202651181), 'edd': np.float64(0.0008675260907957583), 'jsc': np.float64(0.0008229732309511755), 'avatar': np.float64(0.0006682099061850352), 'ooo': np.float64(0.0006682099061850352), 'app': np.float64(0.0006661257200085572), 'asf': np.float64(0.00065519723950384), 'aside': np.float64(0.00065519723950384), 'amc': np.float64(0.0006029277206367138), 'ago': np.float64(0.0005461839581781782), 'accountse': np.float64(0.0005059715590774956), 'assetsa': np.float64(0.0005059715590774956), 'administrator': np.float64(0.0005001199964571082), 'aud': np.float64(0.0004937839385707052), 'ras': np.float64(0.0004876285205428518), 'assetsb': np.float64(0.0004811248822671416), 'authentication': np.float64(0.00045749839012124274), 'era': np.float64(0.0004189518152861614), 'aug': np.float64(0.0004057409958148943), 'apr': np.float64(0.00039943494808064356), 'aid': np.float64(0.00038489044623565193), 'reas': np.float64(0.0003014638603183569), 'asking': np.float64(0.000293594416325018), 'agement': np.float64(0.00026033234920137447), 'afca': np.float64(0.0002500599982285541), 'alfa': np.float64(0.0001822107837104323), 'aum': np.float64(0.00017886577444283622), 'acc': np.float64(0.00015877982105030745), 'apps': np.float64(0.00015034979963322512), 'aiver': np.float64(0.0001444247527058504), 'asse': np.float64(0.0001444247527058504), 'rre': np.float64(0.00012534314236113098), 'ate': np.float64(9.122165946250846e-05), 'ari': np.float64(8.356209490742065e-05), 'aries': np.float64(8.33051643061177e-05), 'arcc': np.float64(7.786573489912293e-05), 'ara': np.float64(7.53427206929459e-05), 'agms': np.float64(1.2612095468501342e-05), 'amf': np.float64(1.2612095468501342e-05), 'anna': np.float64(1.2612095468501342e-05), 'iva': np.float64(1.2612095468501342e-05)}
A3: =IF(COUNTIF(Topic_importance!$A$2:$A$21,Topic_words!B3),1,0) -> 0 | B3: 1 | C3: {'eur': np.float64(0.9914591731667453), 'crr': np.float64(0.06414105771196568), 'rwa': np.float64(0.06408943440143001), 'organisation': np.float64(0.04371825917436218), 'resource': np.float64(0.04198999359037067), 'apply': np.float64(0.03887716665734515), 'arises': np.float64(0.03135428414600905), 'application': np.float64(0.030402466794047536), 'agency': np.float64(0.027598193198046492), 'approximately': np.float64(0.01454754727860801), 'raf': np.float64(0.011124567183344408), 'srep': np.float64(0.01102671043592442), 'aspect': np.float64(0.009015410502376557), 'user': np.float64(0.007994219251268274), 'apart': np.float64(0.007929984314903153), 'roa': np.float64(0.006824592778412507), 'parp': np.float64(0.006070912196299859), 'payer': np.float64(0.005491325562401901), 'irb': np.float64(0.005350809792994664), 'operative': np.float64(0.0051524366353263695), 'creation': np.float64(0.004636020267849089), 'sharing': np.float64(0.003952368113489293), 'ilaap': np.float64(0.0038242501863995993), 'arab': np.float64(0.0027738704782876078), 'irba': np.float64(0.002704297105178147), 'pace': np.float64(0.002374956572283429), 'approver': np.float64(0.0021457650192293247), 'upstream': np.float64(0.0019458371917519465), 'pit': np.float64(0.0019043879362646895), 'npa': np.float64(0.0017168591573698457), 'cpri': np.float64(0.0016349365636020637), 'ease': np.float64(0.0012681854363663302), 'unep': np.float64(0.0012472165830299798), 'alrb': np.float64(0.0010329904661337088), 'apac': np.float64(0.0007635188044080384), 'acpr': np.float64(0.0007265411870056441), 'rrap': np.float64(0.0006600263377147956), 'emapp': np.float64(0.0006104601842939636), 'appraisal': np.float64(0.0006027081163846997), 'appraiser': np.float64(0.0006027081163846997), 'rata': np.float64(0.0006027081163846997), 'pair': np.float64(0.00047010161157612465), 'tap': np.float64(0.0004253099936007928), 'cope': np.float64(0.00041554140875796526), 'rcp': np.float64(0.0003547962455678136), 'sar': np.float64(0.0002974751336395875), 'apparel': np.float64(0.0002752331201635771), 'ran': np.float64(0.00024891966367087326), 'eafe': np.float64(0.0002401598029076222), 'manu': np.float64(0.00021444245086326674), 'rcuv': np.float64(0.0001838449879830238), 'reappraisal': np.float64(0.0001713340891106298), 'ordination': np.float64(0.00016766565976642135), 'orp': np.float64(0.000126362810387379), 'respon': np.float64(8.279039718632902e-05), 'airplus': np.float64(6.237287377578079e-05), 'andersen': np.float64(6.237287377578079e-05), 'anne': np.float64(6.237287377578079e-05), 'aarup': np.float64(6.23728737757553e-05), 'transac': np.float64(4.031777970256807e-05)}
A4: =IF(COUNTIF(Topic_importance!$A$2:$A$21,Topic_words!B4),1,0) -> 0 | B4: 2 | C4: {'decrease': np.float64(0.47067761219051024), 'adverse': np.float64(0.46130538026830126), 'reduction': np.float64(0.3703793388969188), 'mitigation': np.float64(0.31068842106285577), 'reduced': np.float64(0.2538892497758991), 'reduce': np.float64(0.24945496770397627), 'deduction': np.float64(0.2268582770599077), 'mitigate': np.float64(0.19176053634725151), 'adversely': np.float64(0.15296868567879382), 'forborne': np.float64(0.15152541766181443), 'excludes': np.float64(0.14635381593278526), 'mitigating': np.float64(0.11804810438485892), 'reducing': np.float64(0.09942948055866135), 'avoid': np.float64(0.05943769189061195), 'mitigated': np.float64(0.05662746615529307), 'deducted': np.float64(0.056295557211559114), 'termination': np.float64(0.05458751418440104), 'detriment': np.float64(0.04340039485388868), 'cure': np.float64(0.03912697661289086), 'reduces': np.float64(0.03667683395524951), 'exclude': np.float64(0.03493327301685731), 'removal': np.float64(0.023155750666693547), 'lesser': np.float64(0.023075005412071015), 'cease': np.float64(0.02085478962073308), 'minimize': np.float64(0.020641464675850197), 'terminate': np.float64(0.020527942044195772), 'absorb': np.float64(0.019109686107941833), 'mitigates': np.float64(0.01834499338428045), 'remove': np.float64(0.01691639867032511), 'remediate': np.float64(0.015691244724325443), 'censure': np.float64(0.015466490622379222), 'subdued': np.float64(0.015327330213001283), 'eliminate': np.float64(0.01494989537182707), 'minimising': np.float64(0.013373944204823626), 'ceasing': np.float64(0.01300434104026896), 'minimise': np.float64(0.012935427201890793), 'deviate': np.float64(0.011892590531495592), 'mitigant': np.float64(0.011380465772326704), 'combating': np.float64(0.011362527462384907), 'deducting': np.float64(0.011061587280932397), 'abuse': np.float64(0.010006525906090162), 'shrink': np.float64(0.009436142355733812), 'deminimis': np.float64(0.009234406830394776), 'deduct': np.float64(0.008785635024860898), 'downgraded': np.float64(0.008326589096424772), 'avoids': np.float64(0.0077153351975212895), 'modify': np.float64(0.007654478899881115), 'refine': np.float64(0.007036512283011241), 'reprimand': np.float64(0.007010732684945121), 'precluded': np.float64(0.006254157300424734), 'subtracting': np.float64(0.006254157300424734), 'removing': np.float64(0.006221369666839943), 'inhibit': np.float64(0.00618627503887401), 'omitted': np.float64(0.00618627503887401), 'abrupt': np.float64(0.0060841146483055185), 'eliminated': np.float64(0.00602938735975901), 'diminished': np.float64(0.005117893854818197), 'veto': np.float64(0.004978265616100888), 'deductible': np.float64(0.004914895549669453), 'hampered': np.float64(0.004913333802379312), 'narrowed': np.float64(0.004913333802379312), 'trim': np.float64(0.004910861655682038), 'prohibit': np.float64(0.0047461898285474655), 'elimination': np.float64(0.0035899505031996653), 'abused': np.float64(0.0033605480669442835), 'demise': np.float64(0.003276379917151966), 'suppression': np.float64(0.003276379917151966), 'abate': np.float64(0.003276379917151916), 'receded': np.float64(0.0032719909235112625), 'abolished': np.float64(0.003211187029571014), 'refusing': np.float64(0.0031204531449233663), 'foregoing': np.float64(0.0030939405446312033), 'revocation': np.float64(0.0030939405446312033), 'impair': np.float64(0.003092334494242807), 'abreast': np.float64(0.0024977304306035343), 'revert': np.float64(0.002362211765087035), 'aversion': np.float64(0.0023428081066995373), 'amend': np.float64(0.0022343896216189163), 'cured': np.float64(0.0020724317960000376), 'hinders': np.float64(0.0020724317960000376), 'withdraw': np.float64(0.001773462355433842), 'dampened': np.float64(0.0015567231898314035), 'discontinue': np.float64(0.0014748743478390643), 'abated': np.float64(0.0012669360630776754), 'imputed': np.float64(0.0012669360630776754), 'tapering': np.float64(0.001264541661358488), 'curtailment': np.float64(0.0010600052934018095), 'eliminates': np.float64(0.00089400790407993), 'abovementioned': np.float64(0.0008823574076356776), 'terminated': np.float64(0.0007883250643740518), 'lowering': np.float64(0.0007137339113271697), 'waive': np.float64(0.00038045313062054704), 'ated': np.float64(0.00037718147735961454), 'deter': np.float64(7.619137253714825e-05)}
A5: =IF(COUNTIF(Topic_importance!$A$2:$A$21,Topic_words!B5),1,0) -> 0 | B5: 3 | C5: {'compliance': np.float64(0.6311043999646152), 'must': np.float64(0.3923657150183745), 'ensure': np.float64(0.3597359621537454), 'manage': np.float64(0.31617129681773976), 'continue': np.float64(0.2107868909600736), 'accordance': np.float64(0.18647130150146257), 'remains': np.float64(0.15570306266214406), 'maintain': np.float64(0.14770265438556004), 'require': np.float64(0.11244860161566689), 'remain': np.float64(0.11205713669657308), 'remained': np.float64(0.09622039325596), 'hold': np.float64(0.0958444161558508), 'occur': np.float64(0.08481382597613417), 'comply': np.float64(0.07159256799824912), 'adherence': np.float64(0.07125942942583774), 'yield': np.float64(0.06382536224878423), 'allow': np.float64(0.05310975377331543), 'along': np.float64(0.05168028661938788), 'keep': np.float64(0.04645267358018855), 'compliant': np.float64(0.04644765383361652), 'operate': np.float64(0.04392048681858074), 'consist': np.float64(0.04049735713995693), 'rely': np.float64(0.04008893173864574), 'fulfil': np.float64(0.03804731540941544), 'vary': np.float64(0.03267508389460564), 'governed': np.float64(0.03198739951605373), 'incorporate': np.float64(0.03186360022250658), 'believe': np.float64(0.026825057809638078), 'contain': np.float64(0.025618648343723745), 'exist': np.float64(0.024852321306120067), 'accept': np.float64(0.023080776112365434), 'relies': np.float64(0.021348897900019554), 'withstand': np.float64(0.020707915276514492), 'carry': np.float64(0.01860841246249537), 'govern': np.float64(0.018522134756262097), 'shall': np.float64(0.017974401594517377), 'undertake': np.float64(0.017906162671033104), 'living': np.float64(0.016839012929267237), 'incur': np.float64(0.015640175535830685), 'live': np.float64(0.015033708843827395), 'keeping': np.float64(0.015007963680191319), 'stay': np.float64(0.014993854352219177), 'domiciled': np.float64(0.014407677190389039), 'depend': np.float64(0.013891301009984777), 'fulfill': np.float64(0.013012812212861843), 'adhere': np.float64(0.012603623645244358), 'pursue': np.float64(0.011960885571133258), 'complied': np.float64(0.01077382852321748), 'complies': np.float64(0.010466237190654867), 'settle': np.float64(0.010279111348671474), 'adheres': np.float64(0.010178014596140083), 'standby': np.float64(0.010052523483768817), 'engage': np.float64(0.009932133237364322), 'adhering': np.float64(0.009861690723920806), 'adhered': np.float64(0.009588674868754473), 'enforce': np.float64(0.00942881400974528), 'resides': np.float64(0.009295374361819623), 'belong': np.float64(0.008526867872492539), 'suffer': np.float64(0.008095128615434313), 'encompass': np.float64(0.0069059948389385275), 'participate': np.float64(0.006712249272713697), 'complying': np.float64(0.006522026100186325), 'survive': np.float64(0.006347698238439669), 'happen': np.float64(0.0061760809336308875), 'governs': np.float64(0.005838668422782989), 'belonging': np.float64(0.005762336593004389), 'intend': np.float64(0.005172452620098467), 'undergo': np.float64(0.005011132187253556), 'appear': np.float64(0.004877839889578404), 'conform': np.float64(0.003911475863195357), 'succeed': np.float64(0.0037186244945919193), 'necessitate': np.float64(0.003442274758724776), 'therein': np.float64(0.003334323544735957), 'occupy': np.float64(0.003124603420382634), 'existence': np.float64(0.0030466534084096484), 'dwelling': np.float64(0.0030462252943274804), 'presence': np.float64(0.00282972725577944), 'belongs': np.float64(0.0025883485012879854), 'relying': np.float64(0.0025883485012879854), 'substantiate': np.float64(0.0025883485012879854), 'persisted': np.float64(0.002460225960939526), 'sit': np.float64(0.0024056909950420477), 'cooperate': np.float64(0.0023111406108184715), 'navigate': np.float64(0.001871169201184627), 'persist': np.float64(0.0018626305484536415), 'observe': np.float64(0.0018366206330595292), 'habit': np.float64(0.0017873208407753708), 'staying': np.float64(0.0016591983004269107), 'embrace': np.float64(0.0016092901666155174), 'persists': np.float64(0.0014780266209467256), 'refrain': np.float64(0.0014140203407781646), 'proceed': np.float64(0.000929080877690761), 'abide': np.float64(0.0009162078285748468), 'pliance': np.float64(0.0008891182655177012), 'pertains': np.float64(0.0007758792139681591), 'sustain': np.float64(0.0007715554513099426), 'prevail': np.float64(0.0006612496808461714), 'attend': np.float64(0.00013759776482587285)}
A6: =IF(COUNTIF(Topic_importance!$A$2:$A$21,Topic_words!B6),1,0) -> 0 | B6: 4 | C6: {'liability': np.float64(0.7088166659864291), 'impairment': np.float64(0.39380837816378256), 'potential': np.float64(0.3880763633330819), 'responsibility': np.float64(0.20448260825835696), 'available': np.float64(0.19654323789104675), 'adequacy': np.float64(0.14554862667830637), 'ability': np.float64(0.13497695896036577), 'facility': np.float64(0.11312133846930353), 'provided': np.float64(0.11229614124755845), 'capacity': np.float64(0.09881213394660496), 'access': np.float64(0.07776465349260403), 'power': np.float64(0.04799077892657929), 'allocated': np.float64(0.04729526746792276), 'active': np.float64(0.04608429084275007), 'requires': np.float64(0.04330757924568559), 'allocation': np.float64(0.04199224148831205), 'enable': np.float64(0.039258738560596085), 'able': np.float64(0.038808446213274804), 'vulnerability': np.float64(0.035746376183133664), 'capability': np.float64(0.03542881937185697), 'enables': np.float64(0.03375621651094137), 'utility': np.float64(0.033235341194421945), 'dependent': np.float64(0.03265405786872641), 'opportunity': np.float64(0.031537425817183676), 'difficulty': np.float64(0.03073384309440717), 'affordability': np.float64(0.030387573530051313), 'availability': np.float64(0.029602656967303156), 'inclusion': np.float64(0.027833472376179162), 'anticipated': np.float64(0.027414618987596392), 'unable': np.float64(0.02726453049904795), 'awareness': np.float64(0.02593139210799463), 'allows': np.float64(0.025626331219950272), 'limitation': np.float64(0.025340355497626307), 'inability': np.float64(0.023066162665734195), 'advanced': np.float64(0.01971645990465297), 'willing': np.float64(0.019685235733752575), 'encumbered': np.float64(0.017891511331985438), 'allowing': np.float64(0.014976014914176295), 'readily': np.float64(0.013796353267566144), 'competence': np.float64(0.013296523673196128), 'eligibility': np.float64(0.013109000697186967), 'facilitation': np.float64(0.012420180880935156), 'unavailability': np.float64(0.012117747283593836), 'allowed': np.float64(0.010749113033588859), 'liable': np.float64(0.009201119701382862), 'equipment': np.float64(0.008850996836501352), 'enabling': np.float64(0.0081802141941562), 'permitted': np.float64(0.007850942409133574), 'enabled': np.float64(0.007489771389843525), 'skill': np.float64(0.007013939701113597), 'possibility': np.float64(0.006877327755846327), 'recoverability': np.float64(0.006874872937725532), 'authorized': np.float64(0.006617837867821928), 'authorization': np.float64(0.0065226774761210585), 'ment': np.float64(0.00625804691374239), 'reliant': np.float64(0.006166413917008858), 'optionality': np.float64(0.005091164788563524), 'permission': np.float64(0.004897194680778629), 'flexibility': np.float64(0.004554601065870277), 'readiness': np.float64(0.003950110780194624), 'preparedness': np.float64(0.003672819509429227), 'adapting': np.float64(0.0034288352917405287), 'compatible': np.float64(0.0032749277054630486), 'achievement': np.float64(0.0031963693891816176), 'responsiveness': np.float64(0.0031252114726296374), 'disability': np.float64(0.0028403523771299635), 'mobility': np.float64(0.002727334431564875), 'accessible': np.float64(0.002512267549761437), 'impairmentc': np.float64(0.0021164802185886103), 'functionality': np.float64(0.001998151079165305), 'movable': np.float64(0.001904405161049246), 'willingness': np.float64(0.0015821549144818207), 'optionalities': np.float64(0.0015578613664559964), 'adapts': np.float64(0.001426993779043838), 'allowancec': np.float64(0.0014074575678996765), 'attachment': np.float64(0.001401209544212319), 'accommodative': np.float64(0.0013968698344214857), 'ance': np.float64(0.000554865873173674), 'incapacity': np.float64(0.0005289194254446171), 'usability': np.float64(0.0005010041496195421), 'ity': np.float64(0.0004405134657826338), 'resiliency': np.float64(0.0003656125243857103), 'capable': np.float64(0.0003623009556145751), 'compatibility': np.float64(0.00036191804223810307), 'competency': np.float64(0.0003392265678085397), 'sibility': np.float64(0.0003152252467348095), 'ency': np.float64(0.00014888734167010868), 'tainability': np.float64(0.00012371230980545337)}
A7: =IF(COUNTIF(Topic_importance!$A$2:$A$21,Topic_words!B7),1,0) -> 0 | B7: 5 | C7: {'foreign': np.float64(0.7330194967679592), 'different': np.float64(0.41367949649648666), 'negative': np.float64(0.3451272637819334), 'impaired': np.float64(0.2797691355548942), 'elevated': np.float64(0.13510900315252686), 'beyond': np.float64(0.11446969055917629), 'extreme': np.float64(0.11313435257483002), 'normal': np.float64(0.09368669822258421), 'excess': np.float64(0.09225277332018679), 'wrong': np.float64(0.0836334253295862), 'excluded': np.float64(0.061174014453666554), 'inadequate': np.float64(0.05823008873001022), 'deviation': np.float64(0.049805878045952816), 'exceeding': np.float64(0.04731683430805092), 'outlier': np.float64(0.04621050283017248), 'ordinary': np.float64(0.04328110636585845), 'exceptional': np.float64(0.0314707162813453), 'undue': np.float64(0.03023466480453572), 'inappropriate': np.float64(0.029716827745149835), 'exceed': np.float64(0.02811838386789387), 'artificial': np.float64(0.02581540251136979), 'exceeded': np.float64(0.02516572950394151), 'malicious': np.float64(0.023016254761040963), 'unauthorised': np.float64(0.022900548897308484), 'illegal': np.float64(0.021173446590731452), 'excessive': np.float64(0.01875155630907128), 'usual': np.float64(0.01808997065193815), 'illicit': np.float64(0.01543999925135399), 'unacceptable': np.float64(0.01451700319185643), 'unfavourable': np.float64(0.01390535248125257), 'asymmetry': np.float64(0.013473780295349768), 'disrupted': np.float64(0.012662032090204063), 'substandard': np.float64(0.011840977649238887), 'ordinarily': np.float64(0.011184042369654874), 'disorderly': np.float64(0.01112633137653183), 'harmful': np.float64(0.010549229116716257), 'unauthorized': np.float64(0.01051256708705017), 'disruptive': np.float64(0.009710519391348897), 'suspicious': np.float64(0.009163954482399365), 'undesired': np.float64(0.008939185442095156), 'unethical': np.float64(0.008758096654920283), 'unprecedented': np.float64(0.00817078884478759), 'bad': np.float64(0.007836492011534156), 'benign': np.float64(0.007281739337723294), 'flaw': np.float64(0.007156032358750566), 'improper': np.float64(0.0064784753857103266), 'unsuitable': np.float64(0.006356061521130801), 'improperly': np.float64(0.006269014386185159), 'unintended': np.float64(0.006133318077803893), 'abroad': np.float64(0.005754873185230771), 'biased': np.float64(0.005692158987590984), 'unusual': np.float64(0.005364822833396014), 'deviating': np.float64(0.0052857444350306254), 'normally': np.float64(0.005215147207532334), 'undesirable': np.float64(0.005172463326220543), 'unstable': np.float64(0.004977277918600003), 'erroneous': np.float64(0.0041675540142454785), 'erroneously': np.float64(0.0041675540142454785), 'illegally': np.float64(0.0041675540142454785), 'inappropriately': np.float64(0.004123717481025961), 'exogenous': np.float64(0.004003559312410655), 'extraordinary': np.float64(0.00399629338364221), 'inaccurate': np.float64(0.003995371997255412), 'lacking': np.float64(0.003995371997255412), 'unfairly': np.float64(0.0038833822803892295), 'flawed': np.float64(0.0033458294555682193), 'impropriety': np.float64(0.0032392376928551633), 'altered': np.float64(0.0031489733153419372), 'unduly': np.float64(0.003116823828275638), 'contrary': np.float64(0.003059339025594919), 'skewed': np.float64(0.0029884783445050895), 'unaltered': np.float64(0.0029884783445050895), 'unlawfully': np.float64(0.0029884783445050895), 'unforeseen': np.float64(0.0029044312762115834), 'exceptionally': np.float64(0.002497587259713162), 'turbulent': np.float64(0.002470674165953379), 'damaged': np.float64(0.002198298152756987), 'sick': np.float64(0.002188507506885322), 'unconventional': np.float64(0.001983569032530022), 'unlawful': np.float64(0.0019815846917547644), 'unfavorable': np.float64(0.001965764063558415), 'fraudulent': np.float64(0.0019476916528201804), 'sickness': np.float64(0.0018604540903243657), 'unfair': np.float64(0.0015216567513542235), 'altering': np.float64(0.001420563478822999), 'unfavourably': np.float64(0.0014092958945540715), 'toxic': np.float64(0.001195373181557179), 'overly': np.float64(0.0011891062723310255), 'unnecessary': np.float64(0.000524101742426516), 'disturbed': np.float64(0.00045324106133668525), 'unpredicted': np.float64(0.00045324106133668525), 'abnormal': np.float64(0.00042280582571431295), 'uncontrolled': np.float64(0.0003977162962578704), 'rare': np.float64(0.00031486497497550076), 'unexpect': np.float64(0.0001593700474676321)}
A8: =IF(COUNTIF(Topic_importance!$A$2:$A$21,Topic_words!B8),1,0) -> 1 | B8: 6 | C8: {'loss': np.float64(0.9879601824892313), 'excluding': np.float64(0.12850249192443003), 'without': np.float64(0.03798804483524881), 'exemption': np.float64(0.036783936668929054), 'gap': np.float64(0.03166056400394097), 'except': np.float64(0.029619778488020283), 'shortfall': np.float64(0.02795411606723868), 'insufficient': np.float64(0.01810009832378802), 'weakness': np.float64(0.016869250572411187), 'negatively': np.float64(0.014615312510228917), 'deficiency': np.float64(0.01322378562835407), 'lack': np.float64(0.01175460065594728), 'cancellation': np.float64(0.009645018309528814), 'delinquency': np.float64(0.008903375982976202), 'expired': np.float64(0.008613970882240132), 'missing': np.float64(0.007806247734769052), 'withdrawal': np.float64(0.007212449189483454), 'absence': np.float64(0.006826869791420281), 'withdrawn': np.float64(0.006382459038457069), 'evasion': np.float64(0.006020041919542994), 'avoiding': np.float64(0.005471835150793179), 'deficit': np.float64(0.0054502801076992576), 'exclusion': np.float64(0.005075211138771163), 'leaving': np.float64(0.004936612372756857), 'unavailable': np.float64(0.004508457008524348), 'cessation': np.float64(0.004480601372612719), 'ineffectiveness': np.float64(0.004236342664235114), 'absorption': np.float64(0.00418755209779027), 'shortcoming': np.float64(0.004161790777234578), 'fails': np.float64(0.003929277712092206), 'discontinuation': np.float64(0.003743835863730701), 'outage': np.float64(0.003485322765502691), 'shortage': np.float64(0.0034669593272569424), 'inaction': np.float64(0.003200210016181436), 'suspension': np.float64(0.00317928681229051), 'vacancy': np.float64(0.002683661132802587), 'away': np.float64(0.0026831443685401456), 'interruption': np.float64(0.002640030676482481), 'none': np.float64(0.002452001074220664), 'immateriality': np.float64(0.002093776048895135), 'possession': np.float64(0.002093776048895135), 'leakage': np.float64(0.001933034489934879), 'lapse': np.float64(0.0017712664196054355), 'vacant': np.float64(0.0016786367478132018), 'depletion': np.float64(0.001534230466290734), 'null': np.float64(0.0014949895656201804), 'separation': np.float64(0.0014829877673478815), 'dismissal': np.float64(0.001346105882983001), 'illness': np.float64(0.0013132405295483447), 'avoidance': np.float64(0.0012024757433311726), 'ineffectivenes': np.float64(0.0011959916524961441), 'incomplete': np.float64(0.0011709535458185754), 'inaccessibility': np.float64(0.0010019243664332583), 'omission': np.float64(0.0009545282500923268), 'inactive': np.float64(0.0008969937393721083), 'departure': np.float64(0.0007681763122789931), 'missed': np.float64(0.0007681763122789931), 'furlough': np.float64(0.0006376797555076705), 'scarcity': np.float64(0.0005721012652577448), 'attendance': np.float64(0.0005049774927893446), 'inaccessible': np.float64(0.00046504278192815177), 'avoided': np.float64(0.0003152285970809311), 'withholding': np.float64(0.00020873734544378796)}
A9: =IF(COUNTIF(Topic_importance!$A$2:$A$21,Topic_words!B9),1,0) -> 1 | B9: 7 | C9: {'total': np.float64(0.651151716978602), 'value': np.float64(0.6090299604821936), 'amount': np.float64(0.2677165993534033), 'basis': np.float64(0.17714898572731008), 'defined': np.float64(0.13973946314217395), 'quality': np.float64(0.13928468666199575), 'significant': np.float64(0.13073691258686726), 'real': np.float64(0.1268435704984402), 'overall': np.float64(0.07697912666826644), 'physical': np.float64(0.06375033441689762), 'maximum': np.float64(0.05656158255306666), 'amounting': np.float64(0.05060408755815463), 'definition': np.float64(0.045753695335661926), 'full': np.float64(0.03785039857764906), 'base': np.float64(0.03580537420263622), 'actual': np.float64(0.03509922131915546), 'consistent': np.float64(0.03475645651628307), 'relative': np.float64(0.03334824003264418), 'final': np.float64(0.02894640752317672), 'major': np.float64(0.02601511828725262), 'fixed': np.float64(0.025293847688818778), 'zero': np.float64(0.024505744992191915), 'mean': np.float64(0.022448677861344066), 'severity': np.float64(0.01734406390982274), 'recognized': np.float64(0.017123672337408732), 'highest': np.float64(0.015079048159282371), 'greater': np.float64(0.013812508924492038), 'equal': np.float64(0.013617537643301326), 'integral': np.float64(0.011634591505751517), 'whole': np.float64(0.01125444871755929), 'best': np.float64(0.011121075477480712), 'absolute': np.float64(0.009082772457522002), 'sum': np.float64(0.008749316597838694), 'plus': np.float64(0.00855654520366087), 'degree': np.float64(0.008189730969722682), 'constant': np.float64(0.007852917469941592), 'essential': np.float64(0.007590184803549388), 'accepted': np.float64(0.0075576860011875345), 'accuracy': np.float64(0.007340625698371838), 'acceptable': np.float64(0.007165546828366629), 'complete': np.float64(0.006749475877515703), 'fundamental': np.float64(0.006585013649671509), 'prime': np.float64(0.005816943542755235), 'valid': np.float64(0.005606714629497112), 'distinct': np.float64(0.004936015603215158), 'completeness': np.float64(0.004283904632118121), 'exists': np.float64(0.004163908399161203), 'explicit': np.float64(0.0039693133334206725), 'uniform': np.float64(0.003866040642031797), 'ultimate': np.float64(0.0038367029515854927), 'virtual': np.float64(0.0036032268823730663), 'supreme': np.float64(0.003503595181227297), 'entire': np.float64(0.003423775765852932), 'proper': np.float64(0.003326294886541977), 'equating': np.float64(0.0031981394894352254), 'implicit': np.float64(0.0030981412519768456), 'qualification': np.float64(0.0029238212803339024), 'certainty': np.float64(0.0026227751832862425), 'almost': np.float64(0.0025320618714931267), 'permanent': np.float64(0.002418447884065639), 'lasting': np.float64(0.0020672726299544877), 'implicitly': np.float64(0.0019644853373804454), 'max': np.float64(0.001962377587759017), 'inclusive': np.float64(0.0018801686630876486), 'true': np.float64(0.0016381676396175907), 'completely': np.float64(0.0015788484140965892), 'norm': np.float64(0.0012672102265180402), 'perfect': np.float64(0.0011404007720731942), 'bound': np.float64(0.0011325053426768372), 'assert': np.float64(0.0011256320988675928), 'entirety': np.float64(0.0010829975605525569), 'inevitable': np.float64(0.0010057565358999893), 'basic': np.float64(0.0009197018139873969), 'totaling': np.float64(0.0008785356133971603), 'ever': np.float64(0.0008596003274843389), 'unconditionally': np.float64(0.0006592871319136481), 'exactly': np.float64(0.0006213008495722866), 'normalized': np.float64(0.0005696858857517491), 'invalid': np.float64(0.00047663920284509245), 'pure': np.float64(0.0004384249509385842), 'invalidate': np.float64(0.0003844556863277021), 'ness': np.float64(0.0003374589302320105), 'universal': np.float64(0.00030708479591184224), 'anything': np.float64(0.00027496359644127666), 'utmost': np.float64(0.0001988932090428639), 'totalling': np.float64(0.00010653059241917647), 'purely': np.float64(7.490398882599659e-05)}
A10: =IF(COUNTIF(Topic_importance!$A$2:$A$21,Topic_words!B10),1,0) -> 0 | B10: 8 | C10: {'applicable': np.float64(0.5792393313529098), 'managing': np.float64(0.4431176771879983), 'taking': np.float64(0.41671028614480665), 'reflected': np.float64(0.2470337160092208), 'reflects': np.float64(0.21720038454604698), 'acquisition': np.float64(0.20313221921819602), 'applying': np.float64(0.16080332332459524), 'reflecting': np.float64(0.15087014700970228), 'supporting': np.float64(0.11504630890458181), 'captured': np.float64(0.10644115907582197), 'affecting': np.float64(0.10021164679069945), 'implementing': np.float64(0.0992508168235479), 'retained': np.float64(0.09697038406725415), 'assumed': np.float64(0.0927609004064492), 'understanding': np.float64(0.07401889331014617), 'absorbing': np.float64(0.06572554321720023), 'impacting': np.float64(0.06334003308451981), 'focusing': np.float64(0.06052881737094532), 'requiring': np.float64(0.055390197770854764), 'growing': np.float64(0.04650559507631039), 'maturing': np.float64(0.03970207759361074), 'involving': np.float64(0.03390672759337842), 'incorporating': np.float64(0.029106948113800078), 'approving': np.float64(0.02898646495985515), 'becoming': np.float64(0.028548838435804035), 'deriving': np.float64(0.027517621046334484), 'capturing': np.float64(0.026867266812142795), 'aggregating': np.float64(0.023987989083969083), 'integrating': np.float64(0.021545439652302798), 'contributing': np.float64(0.021011685092336214), 'adding': np.float64(0.017095256179434505), 'engaging': np.float64(0.01690284841307919), 'expanding': np.float64(0.015346343089329159), 'encompassing': np.float64(0.015313974018146988), 'earning': np.float64(0.014959218152266035), 'recognising': np.float64(0.01247710293507874), 'gained': np.float64(0.012113092639796413), 'incurring': np.float64(0.01168302329371194), 'participating': np.float64(0.011147682612413192), 'responding': np.float64(0.010731264608036955), 'obtaining': np.float64(0.010596044887424163), 'collecting': np.float64(0.008736985997628005), 'consolidating': np.float64(0.008626712091291962), 'reflective': np.float64(0.008613363570015622), 'retaining': np.float64(0.008593053772069776), 'recognizing': np.float64(0.008477701841166361), 'acquires': np.float64(0.007523002305115337), 'fulfilling': np.float64(0.006886700895499125), 'acquire': np.float64(0.006631927497786615), 'pertaining': np.float64(0.006509551932817706), 'recovering': np.float64(0.006222904642937807), 'containing': np.float64(0.006094048562067822), 'accepting': np.float64(0.005760859871525549), 'accrue': np.float64(0.004805524060972541), 'observing': np.float64(0.004271674749819575), 'accelerating': np.float64(0.004157068757126201), 'passing': np.float64(0.004126896032712663), 'affirming': np.float64(0.003995784810544702), 'collapsing': np.float64(0.003942173469874823), 'emitting': np.float64(0.0038478095749557685), 'attracting': np.float64(0.0038322574403021076), 'employing': np.float64(0.0038322574403021076), 'benefiting': np.float64(0.0038245742244357307), 'consuming': np.float64(0.003698428080679606), 'demanding': np.float64(0.003491215222973518), 'knowing': np.float64(0.003491215222973518), 'repaying': np.float64(0.003491215222973518), 'adjusting': np.float64(0.003487026718322217), 'getting': np.float64(0.0034122549559151252), 'effecting': np.float64(0.003291367381777467), 'fading': np.float64(0.003089933517403928), 'shrinking': np.float64(0.0027562724917687075), 'acknowledging': np.float64(0.002750077204869559), 'accumulation': np.float64(0.0024654521961696334), 'focussing': np.float64(0.002311686935577308), 'occupying': np.float64(0.0022819509902577938), 'paying': np.float64(0.0018889081397908398), 'appreciating': np.float64(0.0013272514542067672), 'ecting': np.float64(0.0013262435649263088), 'acquiring': np.float64(0.0012609862559568163), 'realising': np.float64(0.0011270806878520042), 'adopting': np.float64(0.001055221241939867), 'emphasising': np.float64(0.0008445725038144858), 'amortising': np.float64(0.0006497054374452745), 'embracing': np.float64(0.0005291728618803057)}
A11: =IF(COUNTIF(Topic_importance!$A$2:$A$21,Topic_words!B11),1,0) -> 0 | B11: 9 | C11: {'transaction': np.float64(0.7185588080435882), 'legal': np.float64(0.63103742385366), 'contract': np.float64(0.17787531605496298), 'disposal': np.float64(0.1192841903043854), 'execution': np.float64(0.10769938192742647), 'solvency': np.float64(0.07989423529510739), 'irrevocable': np.float64(0.07673913102375209), 'revocable': np.float64(0.06562375435222742), 'liquidation': np.float64(0.05887726405416587), 'legally': np.float64(0.04694251960153867), 'finma': np.float64(0.03779583055457031), 'closing': np.float64(0.03344676621121604), 'derecognition': np.float64(0.031017070939517638), 'legislation': np.float64(0.028954383798541084), 'closure': np.float64(0.018203360287943803), 'bankruptcy': np.float64(0.015698951371249888), 'completion': np.float64(0.011563242973431928), 'insolvency': np.float64(0.009414696899453132), 'liquidated': np.float64(0.009382308660144379), 'contractually': np.float64(0.008411167400933103), 'ceased': np.float64(0.008147609010093596), 'bundesbank': np.float64(0.008105280009094658), 'amortisation': np.float64(0.0056309883508399855), 'restructurings': np.float64(0.005606476317267224), 'ending': np.float64(0.005253134364283806), 'liquidate': np.float64(0.005173133969689062), 'cancelled': np.float64(0.005062012488232943), 'transacting': np.float64(0.0041944242207475), 'abwicklungsgesetz': np.float64(0.004052640004547345), 'bundesanstalt': np.float64(0.004052640004547329), 'discontinuance': np.float64(0.004052640004547329), 'elapses': np.float64(0.004052640004547329), 'finanzdienstleistungsaufsicht': np.float64(0.004052640004547329), 'kreditwesengesetz': np.float64(0.004052640004547329), 'liquidating': np.float64(0.004052640004547329), 'sanierungs': np.float64(0.004052640004547329), 'rescission': np.float64(0.002413558850109942), 'cassation': np.float64(0.0017103776787805772), 'severance': np.float64(0.0017103776787805772), 'finalization': np.float64(0.0016394475413681051), 'finalisation': np.float64(0.001356865596546579), 'gmbh': np.float64(0.0011402517858537181), 'regula': np.float64(0.000797168688817731), 'verwaltungs': np.float64(0.0001243049186946448), 'terminating': np.float64(8.246601051990132e-05)}
A12: =IF(COUNTIF(Topic_importance!$A$2:$A$21,Topic_words!B12),1,0) -> 1 | B12: 10 | C12: {'credit': np.float64(0.7203035704564746), 'capital': np.float64(0.6210478282745419), 'based': np.float64(0.18440352352795059), 'internal': np.float64(0.15166078754310905), 'assessment': np.float64(0.08747174457081451), 'subject': np.float64(0.08293232417110541), 'profile': np.float64(0.07787412970837579), 'institution': np.float64(0.05007458891816011), 'senior': np.float64(0.04940433737689873), 'authority': np.float64(0.04130955704316903), 'associated': np.float64(0.04061437383273759), 'eligible': np.float64(0.03901418994941375), 'valuation': np.float64(0.03549373342437223), 'principal': np.float64(0.032807540404646625), 'finance': np.float64(0.03206060445733831), 'approved': np.float64(0.03180760773267783), 'personal': np.float64(0.028182690289913374), 'grade': np.float64(0.027830558200402575), 'expert': np.float64(0.018066372274851465), 'structural': np.float64(0.017775232468124222), 'primary': np.float64(0.014819296066196566), 'audit': np.float64(0.014552179542287096), 'benchmark': np.float64(0.01254726925865029), 'master': np.float64(0.012362498590282166), 'published': np.float64(0.011811234471410722), 'professional': np.float64(0.009399506807918487), 'training': np.float64(0.009327981239636777), 'critical': np.float64(0.0087771511078265), 'premium': np.float64(0.0071155366172057375), 'national': np.float64(0.0062991138458836984), 'education': np.float64(0.004872386149347923), 'completed': np.float64(0.004869512527807492), 'political': np.float64(0.004774084633315698), 'scientific': np.float64(0.004677735130114897), 'learning': np.float64(0.00458407119261388), 'learned': np.float64(0.004502484010060915), 'course': np.float64(0.004481520165574054), 'evaluation': np.float64(0.0042392522967681905), 'validated': np.float64(0.0034214589039332755), 'certificate': np.float64(0.0027785822929546396), 'civil': np.float64(0.0020169965022122), 'history': np.float64(0.001905753201020907), 'qualified': np.float64(0.00184247989388481), 'associate': np.float64(0.001811822799133718), 'formal': np.float64(0.001595335171623751), 'secondary': np.float64(0.0015563177725166195), 'background': np.float64(0.0015558987260950688), 'bridge': np.float64(0.0015230492080038746), 'engineering': np.float64(0.0014161519482965746), 'appointed': np.float64(0.0013742029159023834), 'analytics': np.float64(0.001318818004372099), 'credential': np.float64(0.001188032803613249), 'study': np.float64(0.0007094967362463684), 'journal': np.float64(0.0007002656750596502), 'disciplinary': np.float64(0.0006782947482727352), 'career': np.float64(0.0006200979072267092), 'adult': np.float64(0.0005693223602825171), 'academy': np.float64(0.0005659856010221283), 'award': np.float64(0.0004906468945020271), 'university': np.float64(0.0004894090868694406), 'academic': np.float64(0.00046281531069594444), 'medical': np.float64(0.0004436470215324885), 'resume': np.float64(0.0003807349735032376), 'architecture': np.float64(0.000356380591086717), 'exam': np.float64(0.00033946017149698413), 'graduate': np.float64(0.00033702492756686333), 'school': np.float64(0.00029538393376418785), 'curriculum': np.float64(0.00027742565438499225), 'prof': np.float64(0.00014199437448452726), 'english': np.float64(0.00010640032766449662), 'educational': np.float64(9.710843131541499e-05), 'strate': np.float64(7.218018900362069e-05), 'accreditation': np.float64(7.149273232851826e-05), 'credited': np.float64(5.873631407063797e-05), 'american': np.float64(5.869376848825579e-05), 'cred': np.float64(4.7339091192020225e-05)}
A13: =IF(COUNTIF(Topic_importance!$A$2:$A$21,Topic_words!B13),1,0) -> 0 | B13: 11 | C13: {'increase': np.float64(0.6100479595450934), 'leverage': np.float64(0.4490588143183665), 'driven': np.float64(0.40778928765524697), 'advance': np.float64(0.3386937419773019), 'provide': np.float64(0.22098942816715894), 'driver': np.float64(0.14572675121501266), 'forward': np.float64(0.14267937446690512), 'increasing': np.float64(0.10905260695390802), 'enhanced': np.float64(0.08611019294250606), 'attack': np.float64(0.07259234788086437), 'add': np.float64(0.06146725291789239), 'gain': np.float64(0.05999703399695171), 'improve': np.float64(0.051925971836615306), 'achieve': np.float64(0.048358747345370746), 'develop': np.float64(0.046501965994371355), 'enhance': np.float64(0.04544795004870953), 'progress': np.float64(0.03995443715527757), 'drive': np.float64(0.03894635096816444), 'facilitate': np.float64(0.03658798173960615), 'move': np.float64(0.03450622807245219), 'promote': np.float64(0.033113289312258085), 'generate': np.float64(0.032713490248479915), 'strengthen': np.float64(0.0269403084412979), 'escalated': np.float64(0.026281455058695048), 'adapt': np.float64(0.0184087901982204), 'contribute': np.float64(0.018263558533887433), 'exacerbated': np.float64(0.017945153363480473), 'accelerate': np.float64(0.01771538130132947), 'escalate': np.float64(0.017705451624892444), 'enhancing': np.float64(0.016530918080451887), 'steer': np.float64(0.014741874079377134), 'slowdown': np.float64(0.014328375521079849), 'facilitates': np.float64(0.013879497054764165), 'escalating': np.float64(0.012808796296149175), 'facilitating': np.float64(0.011729090633266282), 'expand': np.float64(0.011472916797425571), 'escalates': np.float64(0.011442755212872701), 'ramped': np.float64(0.01027312412056355), 'promotes': np.float64(0.010179868637230909), 'speed': np.float64(0.010074323030331988), 'grow': np.float64(0.01006584310036815), 'rapid': np.float64(0.010052559337261536), 'quickly': np.float64(0.009772213629470944), 'charged': np.float64(0.009274838288408268), 'accelerated': np.float64(0.008412604271110681), 'advancement': np.float64(0.0074716931711884885), 'rapidly': np.float64(0.007413260335621253), 'reinforce': np.float64(0.0069099699522163814), 'empower': np.float64(0.005719548507335514), 'enhances': np.float64(0.005415795274107068), 'swiftly': np.float64(0.005101315060695561), 'prioritise': np.float64(0.005091499709820595), 'acceleration': np.float64(0.004620150032623686), 'transform': np.float64(0.004475827244195684), 'intensified': np.float64(0.004183859340140619), 'ahead': np.float64(0.004101909397507517), 'fast': np.float64(0.0036519002475379897), 'tighten': np.float64(0.0035822866994218616), 'widen': np.float64(0.0035419483466428404), 'emphasise': np.float64(0.0031745278241473987), 'heighten': np.float64(0.0031745278241473987), 'motivate': np.float64(0.0031745278241473987), 'convey': np.float64(0.0029588654465686343), 'velocity': np.float64(0.0019747011770477395), 'stimulate': np.float64(0.0018888611016791871), 'faster': np.float64(0.0018824402223310119), 'initiate': np.float64(0.0018404428521124076), 'encourage': np.float64(0.0016830859110765007), 'mover': np.float64(0.0016274471311501179), 'intensify': np.float64(0.0015903140213435773), 'leap': np.float64(0.0015903140213435773), 'pressurise': np.float64(0.0015842138028038207), 'drove': np.float64(0.0014392970116372224), 'endorse': np.float64(0.0013365786874213316), 'consolidate': np.float64(0.0013067941573479762), 'automate': np.float64(0.001262139817685506), 'boost': np.float64(0.0011216231406388337), 'swift': np.float64(0.00103085581647153), 'broaden': np.float64(0.001026380406204212), 'maximize': np.float64(0.001026380406204212), 'amplify': np.float64(0.0009475031014317422), 'encouraged': np.float64(0.0008435887811120847), 'aggravating': np.float64(0.0007230528961132119), 'converge': np.float64(0.0007230528961132119), 'exponentially': np.float64(0.0005745251972768772), 'prioritize': np.float64(0.0005745251972768772), 'fuelled': np.float64(0.0005555015627719654), 'lengthens': np.float64(0.0003551986941851827), 'incentivise': np.float64(0.00017935717773441898), 'incre': np.float64(0.00016977083448454608)}
... A254: =IF(COUNTIF(Topic_importance!$A$2:$A$21,Topic_words!B254),1,0) -> 0 | B254: 355 | C254: {'seudun': np.float64(1.0), 'signhild': np.float64(0.0), 'sira': np.float64(0.0), 'skullman': np.float64(0.0), 'sufﬁ': np.float64(0.0)}

Sheet Topic_importance
A1: cluster | B1: leading_importance | C1: second_importance
A2: 14 | B2: 1.7957497e+08
A3: 10 | B3: 23142278
A4: 25 | B4: 13746069
A5: 32 | B5: 9880564
A6: 35 | B6: 6788664.7
A7: 7 | B7: 6454535.3
A8: 23 | B8: 6279779.1
A9: 0 | B9: 5858059.4
A10: 220 | B10: 5313909.3
A11: 97 | B11: 4228037.3
A12: 40 | B12: 3459490.8
A13: 76 | B13: 2743987.8
... A21: 72 | B21: 1665591.1

Sheet Tactor Loading
G1: Risk
B2: document | C2: 0 | D2: 6 | E2: 7 | F2: 10 | G2: 14 | H2: 20 | I2: 23 | J2: 25 | K2: 32 | L2: 35 | M2: 40 | N2: 72 | O2: 74 | P2: 75 | Q2: 76 | R2: 95 | S2: 96 | T2: 97 | U2: 112 | V2: 220
B3: 0 | C3: 51.851002 | D3: 16.256712 | E3: 26.384739 | F3: 97.208034 | G3: 375.03324 | H3: 28.261021 | I3: 23.329239 | J3: 30.386693 | K3: 75.952829 | L3: 22.886214 | M3: 28.733223 | N3: 17.242799 | O3: 42.757097 | P3: 12.80601 | Q3: 15.318453 | R3: 7.4221752 | S3: 14.408651 | T3: 60.968428 | U3: 6.0823417 | V3: 28.920885
B4: 1 | C4: 306.08778 | D4: 82.448464 | E4: 274.51616 | F4: 415.05036 | G4: 1255.2543 | H4: 166.87932 | I4: 257.69948 | J4: 433.84638 | K4: 246.61223 | L4: 306.86222 | M4: 239.22045 | N4: 132.38438 | O4: 171.19988 | P4: 169.65558 | Q4: 233.98395 | R4: 18.442321 | S4: 122.63486 | T4: 203.92765 | U4: 331.30013 | V4: 254.23359
B5: 2 | C5: 89.593904 | D5: 80.369672 | E5: 88.613177 | F5: 158.68255 | G5: 376.95829 | H5: 28.346466 | I5: 106.97509 | J5: 65.232164 | K5: 81.955509 | L5: 155.31725 | M5: 56.668944 | N5: 19.647866 | O5: 45.323145 | P5: 32.056812 | Q5: 49.996293 | R5: 65.084435 | S5: 42.538984 | T5: 81.452215 | U5: 65.454006 | V5: 159.5635
B6: 3 | C6: 430.80043 | D6: 289.38459 | E6: 458.13041 | F6: 893.64199 | G6: 1775.6668 | H6: 185.60125 | I6: 300.2922 | J6: 327.92901 | K6: 447.34327 | L6: 373.00803 | M6: 263.04018 | N6: 91.354876 | O6: 216.61521 | P6: 248.512 | Q6: 228.44635 | R6: 304.19681 | S6: 151.64575 | T6: 285.88389 | U6: 158.61524 | V6: 321.45353
B7: 4 | C7: 173.07534 | D7: 104.89638 | E7: 218.6769 | F7: 312.66391 | G7: 1516.8056 | H7: 145.67565 | I7: 346.13357 | J7: 572.00817 | K7: 467.65299 | L7: 230.21074 | M7: 193.62484 | N7: 172.24455 | O7: 86.66805 | P7: 88.673098 | Q7: 111.47116 | R7: 164.15151 | S7: 158.4752 | T7: 228.24771 | U7: 107.82253 | V7: 106.67224
B8: 5 | C8: 36.46027 | D8: 20.030444 | E8: 32.701488 | F8: 141.92388 | G8: 573.86784 | H8: 20.934039 | I8: 98.002564 | J8: 226.7084 | K8: 202.14597 | L8: 71.353702 | M8: 45.739766 | N8: 32.321705 | O8: 114.97004 | P8: 56.683411 | Q8: 38.282646 | R8: 17.092669 | S8: 33.704955 | T8: 45.806265 | U8: 35.221286 | V8: 27.925506
B9: 6 | C9: 28.571858 | D9: 22.089062 | E9: 23.485592 | F9: 56.268777 | G9: 119.11851 | H9: 12.384452 | I9: 31.949681 | J9: 38.21749 | K9: 27.127527 | L9: 18.905042 | M9: 23.39172 | N9: 13.556458 | O9: 24.663616 | P9: 35.28264 | Q9: 26.451461 | R9: 10.103217 | S9: 37.636165 | T9: 22.717879 | U9: 8.103497 | V9: 16.103851
B10: 7 | C10: 118.7783 | D10: 177.10848 | E10: 139.59746 | F10: 286.11451 | G10: 839.18785 | H10: 113.52442 | I10: 219.06099 | J10: 173.52138 | K10: 169.89498 | L10: 118.68617 | M10: 148.5273 | N10: 130.85265 | O10: 105.54203 | P10: 72.910057 | Q10: 140.56796 | R10: 145.04998 | S10: 134.33116 | T10: 166.72636 | U10: 134.3404 | V10: 241.0823
B11: 8 | C11: 52.61925 | D11: 16.14636 | E11: 26.310179 | F11: 97.359695 | G11: 374.02271 | H11: 28.261021 | I11: 23.150731 | J11: 31.520711 | K11: 76.949132 | L11: 22.886214 | M11: 28.733223 | N11: 17.84907 | O11: 42.757097 | P11: 12.776513 | Q11: 14.484706 | R11: 7.4221752 | S11: 14.408651 | T11: 60.968428 | U11: 6.0823417 | V11: 28.920885
B12: 9 | C12: 339.42386 | D12: 101.41025 | E12: 316.43375 | F12: 495.20198 | G12: 1674.6148 | H12: 213.87614 | I12: 307.16552 | J12: 511.6289 | K12: 275.18271 | L12: 349.53829 | M12: 261.71155 | N12: 178.35642 | O12: 178.5729 | P12: 177.08365 | Q12: 247.19361 | R12: 21.664617 | S12: 189.24456 | T12: 245.05426 | U12: 372.69848 | V12: 292.3479
B13: 10 | C13: 106.90674 | D13: 83.685322 | E13: 111.76221 | F13: 221.00748 | G13: 465.86955 | H13: 36.764353 | I13: 133.04162 | J13: 134.2232 | K13: 158.85828 | L13: 182.29964 | M13: 75.807438 | N13: 26.332204 | O13: 65.087997 | P13: 46.068764 | Q13: 52.751456 | R13: 65.674718 | S13: 59.662397 | T13: 101.12361 | U13: 50.413623 | V13: 144.60442
B14: 11 | C14: 448.25916 | D14: 275.29694 | E14: 460.86241 | F14: 963.50621 | G14: 2032.6497 | H14: 196.39489 | I14: 322.38297 | J14: 324.39487 | K14: 502.48913 | L14: 402.03651 | M14: 285.22191 | N14: 92.859457 | O14: 226.24213 | P14: 255.22542 | Q14: 237.57537 | R14: 355.14789 | S14: 169.0051 | T14: 326.99985 | U14: 165.32031 | V14: 368.69581
... B34: 31 | C34: 128.18631 | D34: 128.45737 | E34: 138.70026 | F34: 340.13205 | G34: 1097.0339 | H34: 121.704 | I34: 216.18937 | J34: 205.89404 | K34: 235.64082 | L34: 134.72522 | M34: 111.0738 | N34: 201.34743 | O34: 109.06934 | P34: 69.879234 | Q34: 144.01362 | R34: 22.852795 | S34: 117.62825 | T34: 159.17837 | U34: 108.8612 | V34: 277.02099

Sheet Result 1
A1: C1 | B1: C2 | C1: C3 | D1: C4 | E1: C5 | F1: C6 | G1: C7 | H1: C8 | I1: C9 | J1: C10 | K1: C11 | L1: C12 | M1: C13 | N1: C14 | O1: C15 | P1: C16 | Q1: C17 | R1: C18 | S1: C19 | T1: C20 | U1: C21 | V1: C22 | W1: C23 | X1: C24 | Y1: C25 | Z1: C26 | AA1: C27 | AB1: C28 | AC1: C29 | AD1: C30 | AE1: C31 | AF1: C32 | AG1: C33 | AH1: C34 | AI1: C35 | AJ1: C36 | AK1: C37 | AL1: C38 | AM1: C39 | AN1: C40 | AO1: C41 | AP1: C42 | AQ1: C43 | AR1: C44 | AS1: C45 | AT1: C46 | AU1: C47 | AV1: C48 | AW1: C49 | AX1: C50 | AY1: C51 | AZ1: C52 | BA1: C53 | BB1: C54 | BC1: C55 | BD1: C56 | BE1: C57 | BF1: C58 | BG1: C59 | BH1: C60 | BI1: C61 | BJ1: C62 | BK1: C63 | BL1: C64 | BM1: C65 | BN1: C66 | BO1: C67 | BP1: C68 | BQ1: C69 | BR1: C70 | BS1: C71 | BT1: C72 | BU1: C73 | BV1: C74 | BW1: C75 | BX1: C76 | BY1: C77 | BZ1: C78 | CA1: C79 | CB1: C80 | CC1: C81 | CD1: C82 | CE1: C83 | CF1: C84 | CG1: C85 | CH1: C86 | CI1: C87 | CJ1: C88 | CK1: C89 | CL1: C90 | CM1: C91 | CN1: C92 | CO1: C93 | CP1: C94 | CQ1: C95 | CR1: C96 | CS1: C97 | CT1: C98 | CU1: C99 | CV1: C100 | CW1: C101 | CX1: C102 | CY1: C103 | CZ1: C104 | DA1: C105 | DB1: C106 | DC1: C107 | DD1: C108 | DE1: C109 | DF1: C110 | DG1: C111 | DH1: C112 | DI1: C113 | DJ1: C114 | DK1: C115 | DL1: C116 | DM1: C117 | DN1: C118 | DO1: C119 | DP1: C120 | DQ1: C121 | DR1: C122 | DS1: C123 | DT1: C124 | DU1: C125 | DV1: C126 | DW1: C127 | DX1: C128 | DY1: C129 | DZ1: C130 | EA1: C131 | EB1: C132 | EC1: C133 | ED1: C134 | EE1: C135 | EF1: C136 | EG1: C137 | EH1: C138 | EI1: C139 | EJ1: C140 | EK1: C141 | EL1: C142 | EM1: C143 | EN1: C144 | EO1: C145 | EP1: C146 | EQ1: C147 | ER1: C148 | ES1: C149 | ET1: C150 | EU1: C151 | EV1: C152 | EW1: C153 | EX1: C154 | EY1: C155 | EZ1: C156 | FA1: C157 | FB1: C158 | FC1: C159 | FD1: C160 | FE1: C161 | FF1: C162 | FG1: C163 | FH1: C164 | FI1: C165 | FJ1: C166 | FK1: C167 | FL1: C168 | FM1: C169 | FN1: C170 | FO1: C171 | FP1: C172 | FQ1: C173 | FR1: C174 | FS1: C175 | FT1: C176 | FU1: C177 | FV1: C178 | FW1: C179 | FX1: C180 | FY1: C181 | FZ1: C182 | GA1: C183 | GB1: C184 | GC1: C185 | GD1: C186 | GE1: C187 | GF1: C188 | GG1: C189 | GH1: C190 | GI1: C191 | GJ1: C192 | GK1: C193 | GL1: C194 | GM1: C195 | GN1: C196 | GO1: C197 | GP1: C198 | GQ1: C199 | GR1: C200 | GS1: C201 | GT1: C202 | GU1: C203 | GV1: C204 | GW1: C205 | GX1: C206 | GY1: C207 | GZ1: C208 | HA1: C209 | HB1: C210 | HC1: C211 | HD1: C212 | HE1: C213 | HF1: C214 | HG1: C215 | HH1: C216 | HI1: C217 | HJ1: C218 | HK1: C219 | HL1: C220 | HM1: C221 | HN1: C222 | HO1: C223 | HP1: C224 | HQ1: C225 | HR1: C226 | HS1: C227 | HT1: C228 | HU1: C229 | HV1: C230 | HW1: C231 | HX1: C232 | HY1: C233 | HZ1: C234 | IA1: C235 | IB1: C236 | IC1: C237 | ID1: C238 | IE1: C239 | IF1: C240 | IG1: C241 | IH1: C242 | II1: C243 | IJ1: C244 | IK1: C245 | IL1: C246 | IM1: C247 | IN1: C248 | IO1: C249 | IP1: C250 | IQ1: C251 | IR1: C252 | IS1: C253 | IT1: C254
A2: document | B2: 0 | C2: 1 | D2: 2 | E2: 3 | F2: 4 | G2: 5 | H2: 6 | I2: 7 | J2: 8 | K2: 9 | L2: 10 | M2: 11 | N2: 12 | O2: 13 | P2: 14 | Q2: 15 | R2: 16 | S2: 17 | T2: 18 | U2: 19 | V2: 20 | W2: 21 | X2: 22 | Y2: 23 | Z2: 24 | AA2: 25 | AB2: 26 | AC2: 27 | AD2: 28 | AE2: 29 | AF2: 30 | AG2: 31 | AH2: 32 | AI2: 33 | AJ2: 34 | AK2: 35 | AL2: 36 | AM2: 37 | AN2: 38 | AO2: 39 | AP2: 40 | AQ2: 41 | AR2: 42 | AS2: 43 | AT2: 44 | AU2: 45 | AV2: 46 | AW2: 47 | AX2: 48 | AY2: 49 | AZ2: 50 | BA2: 51 | BB2: 52 | BC2: 53 | BD2: 54 | BE2: 55 | BF2: 56 | BG2: 57 | BH2: 58 | BI2: 59 | BJ2: 60 | BK2: 61 | BL2: 62 | BM2: 63 | BN2: 64 | BO2: 65 | BP2: 66 | BQ2: 67 | BR2: 68 | BS2: 69 | BT2: 70 | BU2: 71 | BV2: 72 | BW2: 73 | BX2: 74 | BY2: 75 | BZ2: 76 | CA2: 77 | CB2: 78 | CC2: 79 | CD2: 80 | CE2: 81 | CF2: 82 | CG2: 83 | CH2: 84 | CI2: 85 | CJ2: 86 | CK2: 87 | CL2: 88 | CM2: 89 | CN2: 90 | CO2: 91 | CP2: 92 | CQ2: 93 | CR2: 94 | CS2: 95 | CT2: 96 | CU2: 97 | CV2: 98 | CW2: 99 | CX2: 100 | CY2: 101 | CZ2: 102 | DA2: 103 | DB2: 104 | DC2: 105 | DD2: 106 | DE2: 107 | DF2: 108 | DG2: 109 | DH2: 110 | DI2: 111 | DJ2: 112 | DK2: 113 | DL2: 114 | DM2: 115 | DN2: 116 | DO2: 117 | DP2: 118 | DQ2: 119 | DR2: 120 | DS2: 121 | DT2: 122 | DU2: 123 | DV2: 124 | DW2: 125 | DX2: 126 | DY2: 127 | DZ2: 128 | EA2: 129 | EB2: 130 | EC2: 131 | ED2: 132 | EE2: 133 | EF2: 134 | EG2: 135 | EH2: 136 | EI2: 137 | EJ2: 138 | EK2: 139 | EL2: 140 | EM2: 141 | EN2: 142 | EO2: 143 | EP2: 144 | EQ2: 145 | ER2: 146 | ES2: 147 | ET2: 148 | EU2: 149 | EV2: 150 | EW2: 151 | EX2: 152 | EY2: 153 | EZ2: 154 | FA2: 155 | FB2: 156 | FC2: 157 | FD2: 158 | FE2: 159 | FF2: 160 | FG2: 161 | FH2: 162 | FI2: 163 | FJ2: 164 | FK2: 166 | FL2: 167 | FM2: 168 | FN2: 169 | FO2: 170 | FP2: 171 | FQ2: 172 | FR2: 173 | FS2: 175 | FT2: 176 | FU2: 177 | FV2: 178 | FW2: 179 | FX2: 180 | FY2: 181 | FZ2: 182 | GA2: 183 | GB2: 184 | GC2: 185 | GD2: 186 | GE2: 188 | GF2: 190 | GG2: 191 | GH2: 194 | GI2: 195 | GJ2: 196 | GK2: 197 | GL2: 198 | GM2: 199 | GN2: 200 | GO2: 201 | GP2: 202 | GQ2: 203 | GR2: 204 | GS2: 205 | GT2: 206 | GU2: 207 | GV2: 208 | GW2: 209 | GX2: 210 | GY2: 211 | GZ2: 212 | HA2: 213 | HB2: 214 | HC2: 215 | HD2: 216 | HE2: 217 | HF2: 219 | HG2: 220 | HH2: 221 | HI2: 223 | HJ2: 224 | HK2: 228 | HL2: 229 | HM2: 230 | HN2: 231 | HO2: 232 | HP2: 233 | HQ2: 234 | HR2: 236 | HS2: 237 | HT2: 241 | HU2: 242 | HV2: 243 | HW2: 245 | HX2: 252 | HY2: 253 | HZ2: 254 | IA2: 256 | IB2: 259 | IC2: 260 | ID2: 261 | IE2: 264 | IF2: 265 | IG2: 270 | IH2: 271 | II2: 272 | IJ2: 273 | IK2: 278 | IL2: 285 | IM2: 288 | IN2: 289 | IO2: 292 | IP2: 296 | IQ2: 298 | IR2: 302 | IS2: 312 | IT2: 355
